2024-12-05 01:22:15,760 INFO    MainThread:78502 [internal.py:wandb_internal():62] W&B internal server running at pid: 78502
2024-12-05 01:22:15,765 DEBUG   HandlerThread:78502 [handler.py:handle_request():54] handle_request: check_version
2024-12-05 01:22:15,765 INFO    WriterThread:78502 [datastore.py:open_for_write():76] open: /home/swkang/codes/on-policy/onpolicy/scripts/results/Hanabi/Hanabi-Full/mappo/check/wandb/run-20241205_012213-raya2zem/run-raya2zem.wandb
2024-12-05 01:22:15,766 DEBUG   SenderThread:78502 [sender.py:send():88] send: header
2024-12-05 01:22:15,767 DEBUG   SenderThread:78502 [sender.py:send():88] send: request
2024-12-05 01:22:15,767 DEBUG   SenderThread:78502 [sender.py:send_request():97] send_request: check_version
2024-12-05 01:22:15,772 DEBUG   Thread-4  :78502 [connectionpool.py:_new_conn():823] Starting new HTTPS connection (1): pypi.org:443
2024-12-05 01:22:15,817 DEBUG   Thread-4  :78502 [connectionpool.py:_make_request():393] https://pypi.org:443 "GET /pypi/wandb/json HTTP/1.1" 200 109254
2024-12-05 01:22:15,852 DEBUG   SenderThread:78502 [sender.py:send():88] send: run
2024-12-05 01:22:15,881 DEBUG   SenderThread:78502 [cmd.py:execute():719] Popen(['git', 'cat-file', '--batch-check'], cwd=/home/swkang/codes/on-policy, universal_newlines=False, shell=None, istream=<valid stream>)
2024-12-05 01:22:15,907 DEBUG   SenderThread:78502 [connectionpool.py:_new_conn():823] Starting new HTTPS connection (1): api.wandb.ai:443
2024-12-05 01:22:16,136 DEBUG   SenderThread:78502 [connectionpool.py:_make_request():393] https://api.wandb.ai:443 "POST /graphql HTTP/1.1" 403 None
2024-12-05 01:22:16,139 ERROR   SenderThread:78502 [internal_api.py:execute():131] 403 response executing GraphQL.
2024-12-05 01:22:16,139 ERROR   SenderThread:78502 [internal_api.py:execute():132] {"errors":[{"message":"permission denied","path":["upsertBucket"],"extensions":{"code":"PERMISSION_ERROR"}}],"data":{"upsertBucket":null}}
2024-12-05 01:22:16,852 INFO    WriterThread:78502 [datastore.py:close():257] close: /home/swkang/codes/on-policy/onpolicy/scripts/results/Hanabi/Hanabi-Full/mappo/check/wandb/run-20241205_012213-raya2zem/run-raya2zem.wandb
2024-12-05 01:22:16,853 INFO    HandlerThread:78502 [handler.py:finish():267] shutting down handler
2024-12-05 01:22:16,854 ERROR   MainThread:78502 [internal.py:wandb_internal():128] Thread SenderThread:
Traceback (most recent call last):
  File "/home/swkang/miniconda3/envs/ppopython7/lib/python3.7/site-packages/wandb/old/retry.py", line 96, in __call__
    result = self._call_fn(*args, **kwargs)
  File "/home/swkang/miniconda3/envs/ppopython7/lib/python3.7/site-packages/wandb/internal/internal_api.py", line 134, in execute
    six.reraise(*sys.exc_info())
  File "/home/swkang/miniconda3/envs/ppopython7/lib/python3.7/site-packages/six.py", line 703, in reraise
    raise value
  File "/home/swkang/miniconda3/envs/ppopython7/lib/python3.7/site-packages/wandb/internal/internal_api.py", line 128, in execute
    return self.client.execute(*args, **kwargs)
  File "/home/swkang/miniconda3/envs/ppopython7/lib/python3.7/site-packages/wandb/vendor/gql-0.2.0/gql/client.py", line 52, in execute
    result = self._get_result(document, *args, **kwargs)
  File "/home/swkang/miniconda3/envs/ppopython7/lib/python3.7/site-packages/wandb/vendor/gql-0.2.0/gql/client.py", line 60, in _get_result
    return self.transport.execute(document, *args, **kwargs)
  File "/home/swkang/miniconda3/envs/ppopython7/lib/python3.7/site-packages/wandb/vendor/gql-0.2.0/gql/transport/requests.py", line 39, in execute
    request.raise_for_status()
  File "/home/swkang/miniconda3/envs/ppopython7/lib/python3.7/site-packages/requests/models.py", line 941, in raise_for_status
    raise HTTPError(http_error_msg, response=self)
requests.exceptions.HTTPError: 403 Client Error: Forbidden for url: https://api.wandb.ai/graphql

During handling of the above exception, another exception occurred:

Traceback (most recent call last):
  File "/home/swkang/miniconda3/envs/ppopython7/lib/python3.7/site-packages/wandb/apis/normalize.py", line 24, in wrapper
    return func(*args, **kwargs)
  File "/home/swkang/miniconda3/envs/ppopython7/lib/python3.7/site-packages/wandb/internal/internal_api.py", line 968, in upsert_run
    response = self.gql(mutation, variable_values=variable_values, **kwargs)
  File "/home/swkang/miniconda3/envs/ppopython7/lib/python3.7/site-packages/wandb/old/retry.py", line 105, in __call__
    if not check_retry_fn(e):
  File "/home/swkang/miniconda3/envs/ppopython7/lib/python3.7/site-packages/wandb/util.py", line 585, in no_retry_auth
    raise CommError("Permission denied, ask the project owner to grant you access")
wandb.errors.error.CommError: Permission denied, ask the project owner to grant you access

During handling of the above exception, another exception occurred:

Traceback (most recent call last):
  File "/home/swkang/miniconda3/envs/ppopython7/lib/python3.7/site-packages/wandb/internal/internal_util.py", line 33, in run
    self._run()
  File "/home/swkang/miniconda3/envs/ppopython7/lib/python3.7/site-packages/wandb/internal/internal_util.py", line 60, in _run
    self._process(record)
  File "/home/swkang/miniconda3/envs/ppopython7/lib/python3.7/site-packages/wandb/internal/internal.py", line 232, in _process
    self._sm.send(record)
  File "/home/swkang/miniconda3/envs/ppopython7/lib/python3.7/site-packages/wandb/internal/sender.py", line 90, in send
    send_handler(record)
  File "/home/swkang/miniconda3/envs/ppopython7/lib/python3.7/site-packages/wandb/internal/sender.py", line 360, in send_run
    self._init_run(run, config_dict)
  File "/home/swkang/miniconda3/envs/ppopython7/lib/python3.7/site-packages/wandb/internal/sender.py", line 396, in _init_run
    commit=repo.last_commit,
  File "/home/swkang/miniconda3/envs/ppopython7/lib/python3.7/site-packages/wandb/apis/normalize.py", line 62, in wrapper
    six.reraise(CommError, CommError(message, err), sys.exc_info()[2])
  File "/home/swkang/miniconda3/envs/ppopython7/lib/python3.7/site-packages/six.py", line 702, in reraise
    raise value.with_traceback(tb)
  File "/home/swkang/miniconda3/envs/ppopython7/lib/python3.7/site-packages/wandb/apis/normalize.py", line 24, in wrapper
    return func(*args, **kwargs)
  File "/home/swkang/miniconda3/envs/ppopython7/lib/python3.7/site-packages/wandb/internal/internal_api.py", line 968, in upsert_run
    response = self.gql(mutation, variable_values=variable_values, **kwargs)
  File "/home/swkang/miniconda3/envs/ppopython7/lib/python3.7/site-packages/wandb/old/retry.py", line 105, in __call__
    if not check_retry_fn(e):
  File "/home/swkang/miniconda3/envs/ppopython7/lib/python3.7/site-packages/wandb/util.py", line 585, in no_retry_auth
    raise CommError("Permission denied, ask the project owner to grant you access")
wandb.errors.error.CommError: Permission denied, ask the project owner to grant you access
2024-12-05 01:22:16,899 INFO    MainThread:78502 [internal.py:handle_exit():137] Internal process exited
